Workbook

Sheet Input
B1: Course Content and Organization | E1: Comments on Course Content and Organization questions (if any) | F1: Student Contribution | H1: Comments on Student Contribution questions (if any) | I1: Learning Environment and Teaching Methods | M1: Comments on Learning Environment and Teaching Methods questions (if any) | N1: Learning Resources | Q1: Comments on Learning Resources questions (if any) | R1: Course Teacher | X1: Comments on Course Teacher questions (if any) | Y1: Criteria for Rating | AE1: Comments on Course Rating criteria (if any) | AF1: Provide feedback to improve the course
A2: Student No. | B2: The course objectives were clear | C2: The course workload was manageable | D2: The course was well organized. (e.g. timely access to materials, notification of changes, etc.) | F2: I participated actively in the course | G2: I think I have made progress in this course | I2: I think the course was well structured to achieve the learning outcomes (There was a good balance of lectures) | J2: The learning and teaching methods encouraged participation | K2: The overall environment in the class was conducive to learning | L2: Classrooms were satisfactory | N2: Learning materials (lesson plans, course notes, etc.) were relevant and useful | O2: Recommended reading books etc. were relevant and appropriate | P2: The provision of learning resources in the library was adequate and appropriate | R2: Course teacher showed empathy and helped solving critical problems | S2: You felt that course teacher is an expert of this course | T2: Delivery skill of teacher was satisfactory | U2: Course teacher responded to your queries | V2: Communication skill of teacher was satisfactory | W2: You felt comfortable expressing your problems to your course teacher | Y2: Course Structure and Contents | Z2: Delivery Quality of Teacher | AA2: Course Duration | AB2: Environment | AC2: New Skill Acquisition/Old Skill Developed | AD2: Overall Rating
B3: Q. 1 | C3: Q. 2 | D3: Q. 3 | E3: Q. 4 | F3: Q. 5 | G3: Q. 6 | H3: Q. 7 | I3: Q. 8 | J3: Q. 9 | K3: Q. 10 | L3: Q. 11 | M3: Q. 12 | N3: Q. 13 | O3: Q. 14 | P3: Q. 15 | Q3: Q. 16 | R3: Q. 17 | S3: Q. 18 | T3: Q. 19 | U3: Q. 20 | V3: Q. 21 | W3: Q. 22 | X3: Q. 23 | Y3: Q. 24 | Z3: Q. 25 | AA3: Q. 26 | AB3: Q. 27 | AC3: Q. 28 | AD3: Q. 29 | AE3: Q. 30 | AF3: Q. 31
A4: 1 | B4: Strongly Agree | C4: Strongly Agree | D4: Strongly Agree | F4: Strongly Agree | G4: Strongly Agree | I4: Strongly Agree | J4: Strongly Agree | K4: Strongly Agree | L4: Strongly Agree | N4: Strongly Agree | O4: Strongly Agree | P4: Strongly Agree | R4: Strongly Agree | S4: Strongly Agree | T4: Strongly Agree | U4: Strongly Agree | V4: Strongly Agree | W4: Strongly Agree | Y4: 5 | Z4: 5 | AA4: 5 | AB4: 5 | AC4: 5 | AD4: 5 | AF4: This was an extremely informative and well-delivered course, providing valuable insights.
A5: 2 | B5: Agree | C5: Agree | D5: Neutral | F5: Agree | G5: Neutral | I5: Neutral | J5: Neutral | K5: Agree | L5: Agree | M5: YT video materials could be provided before each lab as students forget about the lab | N5: Agree | O5: Neutral | P5: Neutral | R5: Agree | S5: Agree | T5: Agree | U5: Agree | V5: Agree | W5: Agree | Y5: 4 | Z5: 4 | AA5: 4 | AB5: 4 | AC5: 4 | AD5: 4 | AF5: give daily assignment to students to watch some short videos on things that will taught in the upcoming lab.
A6: 3 | B6: Strongly Disagree | C6: Disagree | D6: Neutral | F6: Agree | G6: Disagree | I6: Disagree | J6: Disagree | K6: Strongly Disagree | L6: Disagree | N6: Strongly Disagree | O6: Neutral | P6: Disagree | R6: Disagree | S6: Strongly Disagree | T6: Neutral | U6: Neutral | V6: Strongly Agree | W6: Neutral | Y6: 5 | Z6: 1 | AA6: 1 | AB6: 2 | AC6: 3 | AD6: 2 | AF6: nothing
A7: 4 | B7: Strongly Agree | C7: Strongly Agree | D7: Strongly Agree | F7: Strongly Agree | G7: Strongly Agree | I7: Strongly Agree | J7: Strongly Agree | K7: Strongly Agree | L7: Strongly Agree | N7: Strongly Agree | O7: Strongly Agree | P7: Strongly Agree | R7: Strongly Agree | S7: Strongly Agree | T7: Strongly Agree | U7: Strongly Agree | V7: Strongly Agree | W7: Strongly Agree | Y7: 5 | Z7: 5 | AA7: 5 | AB7: 5 | AC7: 5 | AD7: 5 | AF7: The course was very helpful for me.
A8: 5 | B8: Strongly Agree | C8: Strongly Agree | D8: Strongly Agree | F8: Strongly Agree | G8: Strongly Agree | I8: Strongly Agree | J8: Strongly Agree | K8: Strongly Agree | L8: Strongly Agree | N8: Strongly Agree | O8: Strongly Agree | P8: Strongly Agree | R8: Strongly Agree | S8: Strongly Agree | T8: Strongly Agree | U8: Strongly Agree | V8: Strongly Agree | W8: Strongly Agree | Y8: 5 | Z8: 5 | AA8: 5 | AB8: 5 | AC8: 5 | AD8: 5 | AF8: Overall, The course was effective.
A9: 6 | B9: Agree | C9: Agree | D9: Agree | F9: Agree | G9: Agree | I9: Agree | J9: Agree | K9: Agree | L9: Agree | N9: Agree | O9: Agree | P9: Neutral | R9: Agree | S9: Agree | T9: Agree | U9: Agree | V9: Agree | W9: Agree | Y9: 5 | Z9: 5 | AA9: 5 | AB9: 5 | AC9: 5 | AD9: 5 | AF9: Good
A10: 7 | B10: Agree | C10: Agree | D10: Agree | F10: Strongly Agree | G10: Strongly Agree | I10: Agree | J10: Agree | K10: Agree | L10: Agree | N10: Agree | O10: Agree | P10: Agree | R10: Agree | S10: Agree | T10: Agree | U10: Agree | V10: Agree | W10: Agree | Y10: 1 | Z10: 1 | AA10: 1 | AB10: 1 | AC10: 1 | AD10: 1 | AF10: Problem solving
A11: 8 | B11: Strongly Agree | C11: Strongly Agree | D11: Strongly Agree | F11: Strongly Agree | G11: Strongly Agree | I11: Strongly Agree | J11: Strongly Agree | K11: Strongly Agree | L11: Strongly Agree | N11: Strongly Agree | O11: Strongly Agree | P11: Strongly Agree | R11: Strongly Agree | S11: Strongly Agree | T11: Strongly Agree | U11: Strongly Agree | V11: Strongly Agree | W11: Strongly Agree | Y11: 5 | Z11: 5 | AA11: 5 | AB11: 5 | AC11: 5 | AD11: 5 | AF11: Was standard
A12: 9 | B12: Strongly Agree | C12: Disagree | D12: Disagree | F12: Agree | G12: Strongly Agree | I12: Strongly Agree | J12: Strongly Agree | K12: Strongly Agree | L12: Strongly Agree | N12: Strongly Agree | O12: Strongly Agree | P12: Strongly Agree | R12: Strongly Agree | S12: Strongly Agree | T12: Strongly Agree | U12: Strongly Agree | V12: Strongly Agree | W12: Strongly Agree | Y12: 5 | Z12: 5 | AA12: 3 | AB12: 5 | AC12: 5 | AD12: 4 | AF12: In last few days we suffers a lot sir for the unfortunate imbalance time shedule,.so to fulfill our credit course we have to even the last 30 have taken a lab final ,a quiz, a viva and then your presentation and the project submission in the same day. And then we came home after the 5 pm and the next day we have to attend 2 more ct. So sir if the time shedule have been perfect,it would help us .
A13: 10 | B13: Strongly Agree | C13: Strongly Agree | D13: Strongly Agree | F13: Strongly Agree | G13: Strongly Agree | I13: Strongly Agree | J13: Strongly Agree | K13: Strongly Agree | L13: Strongly Agree | N13: Strongly Agree | O13: Neutral | P13: Strongly Agree | R13: Strongly Agree | S13: Agree | T13: Agree | U13: Agree | V13: Strongly Agree | W13: Strongly Agree | Y13: 4 | Z13: 4 | AA13: 5 | AB13: 5 | AC13: 4 | AD13: 4 | AF13: Theory course accompanying this course should've been provided for more detailed learning.
A14: 11 | B14: Strongly Agree | C14: Strongly Agree | D14: Strongly Agree | E14: None | F14: Strongly Agree | G14: Strongly Agree | H14: None | I14: Strongly Agree | J14: Strongly Agree | K14: Strongly Agree | L14: Strongly Agree | M14: None | N14: Strongly Agree | O14: Strongly Agree | P14: Strongly Agree | Q14: None | R14: Strongly Agree | S14: Strongly Agree | T14: Strongly Agree | U14: Strongly Agree | V14: Strongly Agree | W14: Strongly Agree | X14: None | Y14: 5 | Z14: 5 | AA14: 5 | AB14: 5 | AC14: 5 | AD14: 5 | AE14: None | AF14: Course is satisfactory
A15: 12 | B15: Strongly Agree | C15: Agree | D15: Agree | F15: Agree | G15: Agree | I15: Agree | J15: Agree | K15: Agree | L15: Agree | N15: Agree | O15: Agree | P15: Agree | R15: Agree | S15: Agree | T15: Agree | U15: Agree | V15: Agree | W15: Agree | Y15: 4 | Z15: 5 | AA15: 4 | AB15: 5 | AC15: 4 | AD15: 4 | AF15: good
A16: 13 | B16: Strongly Agree | C16: Strongly Agree | D16: Strongly Agree | F16: Strongly Agree | G16: Strongly Agree | I16: Strongly Agree | J16: Strongly Agree | K16: Strongly Agree | L16: Strongly Agree | N16: Strongly Agree | O16: Strongly Agree | P16: Strongly Agree | R16: Strongly Agree | S16: Strongly Agree | T16: Strongly Agree | U16: Strongly Agree | V16: Strongly Agree | W16: Strongly Agree | Y16: 5 | Z16: 5 | AA16: 5 | AB16: 5 | AC16: 5 | AD16: 5 | AF16: The course was quite good.
A17: 14 | B17: Strongly Agree | C17: Strongly Agree | D17: Strongly Agree | F17: Strongly Agree | G17: Strongly Agree | I17: Strongly Agree | J17: Strongly Agree | K17: Strongly Agree | L17: Strongly Agree | N17: Strongly Agree | O17: Strongly Agree | P17: Strongly Agree | R17: Strongly Agree | S17: Strongly Agree | T17: Strongly Agree | U17: Strongly Agree | V17: Strongly Agree | W17: Strongly Agree | Y17: 5 | Z17: 5 | AA17: 5 | AB17: 5 | AC17: 5 | AD17: 5 | AF17: very good
A18: 15 | B18: Agree | C18: Agree | D18: Strongly Agree | F18: Strongly Agree | G18: Agree | I18: Strongly Agree | J18: Strongly Agree | K18: Strongly Agree | L18: Agree | N18: Strongly Agree | O18: Strongly Agree | P18: Strongly Agree | R18: Strongly Agree | S18: Strongly Agree | T18: Strongly Agree | U18: Strongly Agree | V18: Strongly Agree | W18: Strongly Agree | Y18: 5 | Z18: 5 | AA18: 4 | AB18: 5 | AC18: 4 | AD18: 5 | AF18: The course was overall good, I think some more time should be given on the class for the concepts. And for gaming projects, some extra skills are needed to teach the students. It will boost us to make some more dynamic gaming project
A19: 16 | B19: Agree | C19: Agree | D19: Agree | F19: Agree | G19: Agree | I19: Agree | J19: Neutral | K19: Strongly Agree | L19: Agree | N19: Agree | O19: Neutral | P19: Agree | R19: Agree | S19: Agree | T19: Agree | U19: Neutral | V19: Agree | W19: Neutral | Y19: 4 | Z19: 4 | AA19: 3 | AB19: 4 | AC19: 3 | AD19: 4 | AF19: The course was satisfactory
A20: 17 | B20: Agree | C20: Agree | D20: Agree | F20: Agree | G20: Agree | I20: Agree | J20: Agree | K20: Agree | L20: Agree | N20: Agree | O20: Agree | P20: Agree | R20: Agree | S20: Agree | T20: Agree | U20: Agree | V20: Agree | W20: Agree | Y20: 5 | Z20: 4 | AA20: 5 | AB20: 4 | AC20: 4 | AD20: 5 | AF20: N/A
A21: 18 | B21: Strongly Agree | C21: Strongly Agree | D21: Agree | F21: Agree | G21: Agree | I21: Agree | J21: Agree | K21: Agree | L21: Agree | N21: Agree | O21: Agree | P21: Agree | R21: Agree | S21: Agree | T21: Strongly Agree | U21: Strongly Agree | V21: Agree | W21: Agree | Y21: 4 | Z21: 4 | AA21: 4 | AB21: 4 | AC21: 4 | AD21: 4 | AF21: This course was very satisfactory,
A22: 19 | B22: Strongly Agree | C22: Strongly Agree | D22: Strongly Agree | F22: Strongly Agree | G22: Strongly Agree | I22: Strongly Agree | J22: Strongly Agree | K22: Strongly Agree | L22: Strongly Agree | N22: Strongly Agree | O22: Strongly Agree | P22: Strongly Agree | R22: Strongly Agree | S22: Strongly Agree | T22: Strongly Agree | U22: Strongly Agree | V22: Strongly Agree | W22: Strongly Agree | Y22: 5 | Z22: 5 | AA22: 5 | AB22: 5 | AC22: 5 | AD22: 5 | AF22: Course was well organized.
A23: 20 | B23: Agree | C23: Agree | D23: Agree | F23: Agree | G23: Agree | I23: Neutral | J23: Neutral | K23: Disagree | L23: Disagree | N23: Neutral | O23: Agree | P23: Agree | R23: Agree | S23: Agree | T23: Agree | U23: Agree | V23: Agree | W23: Agree | Y23: 3 | Z23: 3 | AA23: 3 | AB23: 3 | AC23: 3 | AD23: 3 | AF23: I am satisfied.
A24: 21 | B24: Strongly Agree | C24: Agree | D24: Strongly Agree | F24: Strongly Agree | G24: Strongly Agree | I24: Strongly Agree | J24: Strongly Agree | K24: Strongly Agree | L24: Strongly Agree | N24: Strongly Agree | O24: Strongly Agree | P24: Strongly Agree | R24: Strongly Agree | S24: Strongly Agree | T24: Strongly Agree | U24: Strongly Agree | V24: Strongly Agree | W24: Strongly Agree | Y24: 5 | Z24: 5 | AA24: 4 | AB24: 5 | AC24: 5 | AD24: 5 | AF24: It is well enough.
A25: 22 | B25: Strongly Agree | C25: Strongly Agree | D25: Strongly Agree | F25: Strongly Agree | G25: Strongly Agree | I25: Strongly Agree | J25: Strongly Agree | K25: Strongly Agree | L25: Strongly Agree | N25: Strongly Agree | O25: Strongly Agree | P25: Strongly Agree | R25: Strongly Agree | S25: Strongly Agree | T25: Strongly Agree | U25: Strongly Agree | V25: Strongly Agree | W25: Strongly Agree | Y25: 5 | Z25: 5 | AA25: 5 | AB25: 5 | AC25: 5 | AD25: 5 | AF25: Satisfied by taking this course.
A26: 23 | B26: Strongly Agree | C26: Strongly Agree | D26: Strongly Agree | F26: Strongly Agree | G26: Strongly Agree | I26: Strongly Agree | J26: Strongly Agree | K26: Strongly Agree | L26: Strongly Agree | N26: Strongly Agree | O26: Strongly Agree | P26: Strongly Agree | R26: Strongly Agree | S26: Strongly Agree | T26: Strongly Agree | U26: Strongly Agree | V26: Strongly Agree | W26: Strongly Agree | X26: Course teacher was very friendly and helpful. | Y26: 5 | Z26: 5 | AA26: 5 | AB26: 5 | AC26: 5 | AD26: 5 | AF26: Course is well organized.
A27: 24 | B27: Strongly Agree | C27: Strongly Agree | D27: Strongly Agree | F27: Strongly Agree | G27: Strongly Agree | I27: Strongly Agree | J27: Strongly Agree | K27: Strongly Agree | L27: Strongly Agree | N27: Strongly Agree | O27: Strongly Agree | P27: Strongly Agree | R27: Strongly Agree | S27: Strongly Agree | T27: Strongly Agree | U27: Strongly Agree | V27: Strongly Agree | W27: Strongly Agree | Y27: 5 | Z27: 5 | AA27: 5 | AB27: 4 | AC27: 5 | AD27: 5 | AF27: Nothing, overall good.
A28: 25 | B28: Strongly Agree | C28: Agree | D28: Strongly Agree | F28: Agree | G28: Strongly Agree | I28: Agree | J28: Strongly Agree | K28: Agree | L28: Strongly Agree | N28: Agree | O28: Strongly Agree | P28: Agree | R28: Strongly Agree | S28: Agree | T28: Strongly Agree | U28: Agree | V28: Strongly Agree | W28: Strongly Agree | Y28: 4 | Z28: 5 | AA28: 4 | AB28: 5 | AC28: 5 | AD28: 5 | AF28: Overall well.
A29: 26 | B29: Strongly Agree | C29: Strongly Agree | D29: Strongly Agree | F29: Agree | G29: Neutral | I29: Agree | J29: Agree | K29: Agree | L29: Agree | N29: Strongly Agree | O29: Agree | P29: Strongly Agree | R29: Strongly Agree | S29: Strongly Agree | T29: Strongly Agree | U29: Strongly Agree | V29: Strongly Agree | W29: Strongly Agree | Y29: 5 | Z29: 5 | AA29: 3 | AB29: 5 | AC29: 3 | AD29: 5 | AF29: Perfect.
A30: 27 | B30: Strongly Agree | C30: Strongly Agree | D30: Strongly Agree | F30: Strongly Agree | G30: Strongly Agree | I30: Strongly Agree | J30: Strongly Agree | K30: Strongly Agree | L30: Strongly Agree | N30: Strongly Agree | O30: Strongly Agree | P30: Strongly Agree | R30: Strongly Agree | S30: Strongly Agree | T30: Strongly Agree | U30: Strongly Agree | V30: Strongly Agree | W30: Strongly Agree | Y30: 5 | Z30: 5 | AA30: 5 | AB30: 5 | AC30: 5 | AD30: 5 | AF30: Already so organized. Teaching style and lectures are very helpful.
A31: 28 | B31: Strongly Agree | C31: Strongly Agree | D31: Strongly Agree | F31: Strongly Agree | G31: Strongly Agree | I31: Strongly Agree | J31: Strongly Agree | K31: Strongly Agree | L31: Strongly Agree | N31: Strongly Agree | O31: Strongly Agree | P31: Strongly Agree | R31: Strongly Agree | S31: Strongly Agree | T31: Strongly Agree | U31: Strongly Agree | V31: Strongly Agree | W31: Strongly Agree | Y31: 5 | Z31: 5 | AA31: 5 | AB31: 5 | AC31: 5 | AD31: 5 | AF31: Overall good.
A32: 29 | B32: Strongly Agree | C32: Strongly Agree | D32: Strongly Agree | F32: Strongly Agree | G32: Strongly Agree | I32: Strongly Agree | J32: Strongly Agree | K32: Strongly Agree | L32: Strongly Agree | N32: Strongly Agree | O32: Strongly Agree | P32: Strongly Agree | R32: Strongly Agree | S32: Strongly Agree | T32: Strongly Agree | U32: Strongly Agree | V32: Strongly Agree | W32: Strongly Agree | Y32: 5 | Z32: 5 | AA32: 5 | AB32: 5 | AC32: 5 | AD32: 5 | AF32: The course was satisfactory.
A33: 30 | B33: Strongly Agree | C33: Strongly Agree | D33: Strongly Agree | F33: Agree | G33: Agree | I33: Strongly Agree | J33: Strongly Agree | K33: Strongly Agree | L33: Strongly Agree | N33: Strongly Agree | O33: Strongly Agree | P33: Strongly Agree | R33: Agree | S33: Agree | T33: Agree | U33: Strongly Agree | V33: Strongly Agree | W33: Strongly Agree | Y33: 5 | Z33: 4 | AA33: 4 | AB33: 4 | AC33: 4 | AD33: 4 | AF33: The lectures were clear and easy to follow.
A34: 31 | B34: Strongly Agree | C34: Strongly Agree | D34: Strongly Agree | F34: Strongly Agree | G34: Strongly Agree | I34: Strongly Agree | J34: Strongly Agree | K34: Strongly Agree | L34: Strongly Agree | N34: Strongly Agree | O34: Strongly Agree | P34: Agree | R34: Strongly Agree | S34: Agree | T34: Strongly Agree | U34: Strongly Agree | V34: Agree | W34: Strongly Agree | Y34: 5 | Z34: 5 | AA34: 5 | AB34: 5 | AC34: 5 | AD34: 5 | AF34: Teaching method was excellent.
A35: 32 | B35: Strongly Agree | C35: Strongly Agree | D35: Strongly Agree | F35: Strongly Agree | G35: Strongly Agree | I35: Strongly Agree | J35: Strongly Agree | K35: Strongly Agree | L35: Strongly Agree | N35: Strongly Agree | O35: Strongly Agree | P35: Strongly Agree | R35: Strongly Agree | S35: Strongly Agree | T35: Strongly Agree | U35: Strongly Agree | V35: Strongly Agree | W35: Strongly Agree | Y35: 5 | Z35: 5 | AA35: 5 | AB35: 5 | AC35: 5 | AD35: 5 | AF35: Everything was arranged properly.
A36: 33 | B36: Agree | C36: Agree | D36: Agree | F36: Agree | G36: Agree | I36: Agree | J36: Agree | K36: Agree | L36: Agree | N36: Agree | O36: Agree | P36: Agree | R36: Agree | S36: Agree | T36: Agree | U36: Agree | V36: Agree | W36: Agree | Y36: 4 | Z36: 4 | AA36: 4 | AB36: 4 | AC36: 4 | AD36: 4 | AF36: Very helpful and well-structured course.
A37: 34 | B37: Agree | C37: Agree | D37: Agree | F37: Agree | G37: Agree | I37: Agree | J37: Agree | K37: Agree | L37: Agree | N37: Agree | O37: Agree | P37: Agree | R37: Agree | S37: Agree | T37: Agree | U37: Agree | V37: Agree | W37: Agree | Y37: 5 | Z37: 4 | AA37: 5 | AB37: 4 | AC37: 4 | AD37: 5 | AF37: Overall good.
A38: 35
A39: 36
A40: 37
...

Sheet Graphs
C2: Total Participants : | F2: =65-COUNTIF(Input!B4:B68,"") -> 34
B5: Criterias | C5: Question Nos.
B7: =Input!B1 -> Course Content and Organization
C8: =Input!B3 -> Q. 1 | D8: =Input!C3 -> Q. 2 | E8: =Input!D3 -> Q. 3
B9: Strongly Agree | C9: =COUNTIF(Input!B$4:'Input'!B$68, "Strongly Agree")/$F$2*100 -> 70.588235 | D9: =COUNTIF(Input!C$4:'Input'!C$68, "Strongly Agree")/$F$2*100 -> 58.823529 | E9: =COUNTIF(Input!D$4:'Input'!D$68, "Strongly Agree")/$F$2*100 -> 64.705882
B10: Agree | C10: =COUNTIF(Input!B$4:'Input'!B$68, "Agree")/$F$2*100 -> 26.470588 | D10: =COUNTIF(Input!C$4:'Input'!C$68, "Agree")/$F$2*100 -> 35.294118 | E10: =COUNTIF(Input!D$4:'Input'!D$68, "Agree")/$F$2*100 -> 26.470588
B11: Neutral | C11: =COUNTIF(Input!B$4:B$68, "Neutral")/$F$2*100 -> 0 | D11: =COUNTIF(Input!C$4:C$68, "Neutral")/$F$2*100 -> 0 | E11: =COUNTIF(Input!D$4:D$68, "Neutral")/$F$2*100 -> 5.8823529
B12: Disagree | C12: =COUNTIF(Input!B$4:'Input'!B$68, "Disagree")/$F$2*100 -> 0 | D12: =COUNTIF(Input!C$4:'Input'!C$68, "Disagree")/$F$2*100 -> 5.8823529 | E12: =COUNTIF(Input!D$4:'Input'!D$68, "Disagree")/$F$2*100 -> 2.9411765
B13: Strongly Disagree | C13: =COUNTIF(Input!B$4:'Input'!B$68, "Strongly Disagree")/$F$2*100 -> 2.9411765 | D13: =COUNTIF(Input!C$4:'Input'!C$68, "Strongly Disagree")/$F$2*100 -> 0 | E13: =COUNTIF(Input!D$4:'Input'!D$68, "Strongly Disagree")/$F$2*100 -> 0
B16: =Input!F1 -> Student Contribution
C17: =Input!F3 -> Q. 5 | D17: =Input!G3 -> Q. 6
B18: Strongly Agree | C18: =COUNTIF(Input!F$4:'Input'!F$68, "Strongly Agree")/$F$2*100 -> 58.823529 | D18: =COUNTIF(Input!G$4:'Input'!G$68, "Strongly Agree")/$F$2*100 -> 61.764706
B19: Agree | C19: =COUNTIF(Input!F$4:'Input'!F$68, "Agree")/$F$2*100 -> 41.176471 | D19: =COUNTIF(Input!G$4:'Input'!G$68, "Agree")/$F$2*100 -> 29.411765
B20: Neutral | C20: =COUNTIF(Input!F$4:F$68, "Neutral")/$F$2*100 -> 0 | D20: =COUNTIF(Input!G$4:G$68, "Neutral")/$F$2*100 -> 5.8823529
B21: Disagree | C21: =COUNTIF(Input!F$4:'Input'!F$68, "Disagree")/$F$2*100 -> 0 | D21: =COUNTIF(Input!G$4:'Input'!G$68, "Disagree")/$F$2*100 -> 2.9411765
B22: Strongly Disagree | C22: =COUNTIF(Input!F$4:'Input'!F$68, "Strongly Disagree")/$F$2*100 -> 0 | D22: =COUNTIF(Input!G$4:'Input'!G$68, "Strongly Disagree")/$F$2*100 -> 0
B25: =Input!I1 -> Learning Environment and Teaching Methods
C26: =Input!I3 -> Q. 8 | D26: =Input!J3 -> Q. 9 | E26: =Input!K3 -> Q. 10 | F26: =Input!L3 -> Q. 11
B27: Strongly Agree | C27: =COUNTIF(Input!I$4:'Input'!I$68, "Strongly Agree")/$F$2*100 -> 61.764706 | D27: =COUNTIF(Input!J$4:'Input'!J$68, "Strongly Agree")/$F$2*100 -> 64.705882 | E27: =COUNTIF(Input!K$4:'Input'!K$68, "Strongly Agree")/$F$2*100 -> 64.705882 | F27: =COUNTIF(Input!L$4:'Input'!L$68, "Strongly Agree")/$F$2*100 -> 61.764706
B28: Agree | C28: =COUNTIF(Input!I$4:'Input'!I$68, "Agree")/$F$2*100 -> 29.411765 | D28: =COUNTIF(Input!J$4:'Input'!J$68, "Agree")/$F$2*100 -> 23.529412 | E28: =COUNTIF(Input!K$4:'Input'!K$68, "Agree")/$F$2*100 -> 29.411765 | F28: =COUNTIF(Input!L$4:'Input'!L$68, "Agree")/$F$2*100 -> 32.352941
B29: Neutral | C29: =COUNTIF(Input!I$4:I$68, "Neutral")/$F$2*100 -> 5.8823529 | D29: =COUNTIF(Input!J$4:J$68, "Neutral")/$F$2*100 -> 8.8235294 | E29: =COUNTIF(Input!K$4:K$68, "Neutral")/$F$2*100 -> 0 | F29: =COUNTIF(Input!L$4:L$68, "Neutral")/$F$2*100 -> 0
B30: Disagree | C30: =COUNTIF(Input!I$4:'Input'!I$68, "Disagree")/$F$2*100 -> 2.9411765 | D30: =COUNTIF(Input!J$4:'Input'!J$68, "Disagree")/$F$2*100 -> 2.9411765 | E30: =COUNTIF(Input!K$4:'Input'!K$68, "Disagree")/$F$2*100 -> 2.9411765 | F30: =COUNTIF(Input!L$4:'Input'!L$68, "Disagree")/$F$2*100 -> 5.8823529
B31: Strongly Disagree | C31: =COUNTIF(Input!I$4:'Input'!I$68, "Strongly Disagree")/$F$2*100 -> 0 | D31: =COUNTIF(Input!J$4:'Input'!J$68, "Strongly Disagree")/$F$2*100 -> 0 | E31: =COUNTIF(Input!K$4:'Input'!K$68, "Strongly Disagree")/$F$2*100 -> 2.9411765 | F31: =COUNTIF(Input!L$4:'Input'!L$68, "Strongly Disagree")/$F$2*100 -> 0
B34: =Input!N1 -> Learning Resources
C35: =Input!N3 -> Q. 13 | D35: =Input!O3 -> Q. 14 | E35: =Input!P3 -> Q. 15
B36: Strongly Agree | C36: =COUNTIF(Input!N$4:'Input'!N$68, "Strongly Agree")/$F$2*100 -> 64.705882 | D36: =COUNTIF(Input!O$4:'Input'!O$68, "Strongly Agree")/$F$2*100 -> 61.764706 | E36: =COUNTIF(Input!P$4:'Input'!P$68, "Strongly Agree")/$F$2*100 -> 61.764706
B37: Agree | C37: =COUNTIF(Input!N$4:'Input'!N$68, "Agree")/$F$2*100 -> 29.411765 | D37: =COUNTIF(Input!O$4:'Input'!O$68, "Agree")/$F$2*100 -> 26.470588 | E37: =COUNTIF(Input!P$4:'Input'!P$68, "Agree")/$F$2*100 -> 29.411765
B38: Neutral | C38: =COUNTIF(Input!N$4:N$68, "Neutral")/$F$2*100 -> 2.9411765 | D38: =COUNTIF(Input!O$4:O$68, "Neutral")/$F$2*100 -> 11.764706 | E38: =COUNTIF(Input!P$4:P$68, "Neutral")/$F$2*100 -> 5.8823529
B39: Disagree | C39: =COUNTIF(Input!N$4:'Input'!N$68, "Disagree")/$F$2*100 -> 0 | D39: =COUNTIF(Input!O$4:'Input'!O$68, "Disagree")/$F$2*100 -> 0 | E39: =COUNTIF(Input!P$4:'Input'!P$68, "Disagree")/$F$2*100 -> 2.9411765
B40: Strongly Disagree | C40: =COUNTIF(Input!N$4:'Input'!N$68, "Strongly Disagree")/$F$2*100 -> 2.9411765 | D40: =COUNTIF(Input!O$4:'Input'!O$68, "Strongly Disagree")/$F$2*100 -> 0 | E40: =COUNTIF(Input!P$4:'Input'!P$68, "Strongly Disagree")/$F$2*100 -> 0
B43: =Input!R1 -> Course Teacher
C44: =Input!R3 -> Q. 17 | D44: =Input!S3 -> Q. 18 | E44: =Input!T3 -> Q. 19 | F44: =Input!U3 -> Q. 20 | G44: =Input!V3 -> Q. 21 | H44: =Input!W3 -> Q. 22
B45: Strongly Agree | C45: =COUNTIF(Input!R$4:'Input'!R$68, "Strongly Agree")/$F$2*100 -> 64.705882 | D45: =COUNTIF(Input!S$4:'Input'!S$68, "Strongly Agree")/$F$2*100 -> 55.882353 | E45: =COUNTIF(Input!T$4:'Input'!T$68, "Strongly Agree")/$F$2*100 -> 64.705882 | F45: =COUNTIF(Input!U$4:'Input'!U$68, "Strongly Agree")/$F$2*100 -> 64.705882 | G45: =COUNTIF(Input!V$4:'Input'!V$68, "Strongly Agree")/$F$2*100 -> 67.647059 | H45: =COUNTIF(Input!W$4:'Input'!W$68, "Strongly Agree")/$F$2*100 -> 67.647059
B46: Agree | C46: =COUNTIF(Input!R$4:'Input'!R$68, "Agree")/$F$2*100 -> 32.352941 | D46: =COUNTIF(Input!S$4:'Input'!S$68, "Agree")/$F$2*100 -> 41.176471 | E46: =COUNTIF(Input!T$4:'Input'!T$68, "Agree")/$F$2*100 -> 32.352941 | F46: =COUNTIF(Input!U$4:'Input'!U$68, "Agree")/$F$2*100 -> 29.411765 | G46: =COUNTIF(Input!V$4:'Input'!V$68, "Agree")/$F$2*100 -> 32.352941 | H46: =COUNTIF(Input!W$4:'Input'!W$68, "Agree")/$F$2*100 -> 26.470588
B47: Neutral | C47: =COUNTIF(Input!R$4:R$68, "Neutral")/$F$2*100 -> 0 | D47: =COUNTIF(Input!S$4:S$68, "Neutral")/$F$2*100 -> 0 | E47: =COUNTIF(Input!T$4:T$68, "Neutral")/$F$2*100 -> 2.9411765 | F47: =COUNTIF(Input!U$4:U$68, "Neutral")/$F$2*100 -> 5.8823529 | G47: =COUNTIF(Input!V$4:V$68, "Neutral")/$F$2*100 -> 0 | H47: =COUNTIF(Input!W$4:W$68, "Neutral")/$F$2*100 -> 5.8823529
B48: Disagree | C48: =COUNTIF(Input!R$4:'Input'!R$68, "Disagree")/$F$2*100 -> 2.9411765 | D48: =COUNTIF(Input!S$4:'Input'!S$68, "Disagree")/$F$2*100 -> 0 | E48: =COUNTIF(Input!T$4:'Input'!T$68, "Disagree")/$F$2*100 -> 0 | F48: =COUNTIF(Input!U$4:'Input'!U$68, "Disagree")/$F$2*100 -> 0 | G48: =COUNTIF(Input!V$4:'Input'!V$68, "Disagree")/$F$2*100 -> 0 | H48: =COUNTIF(Input!W$4:'Input'!W$68, "Disagree")/$F$2*100 -> 0
B49: Strongly Disagree | C49: =COUNTIF(Input!R$4:'Input'!R$68, "Strongly Disagree")/$F$2*100 -> 0 | D49: =COUNTIF(Input!S$4:'Input'!S$68, "Strongly Disagree")/$F$2*100 -> 2.9411765 | E49: =COUNTIF(Input!T$4:'Input'!T$68, "Strongly Disagree")/$F$2*100 -> 0 | F49: =COUNTIF(Input!U$4:'Input'!U$68, "Strongly Disagree")/$F$2*100 -> 0 | G49: =COUNTIF(Input!V$4:'Input'!V$68, "Strongly Disagree")/$F$2*100 -> 0 | H49: =COUNTIF(Input!W$4:'Input'!W$68, "Strongly Disagree")/$F$2*100 -> 0
B52: =Input!Y1 -> Criteria for Rating
C53: =Input!Y3 -> Q. 24 | D53: =Input!Z3 -> Q. 25 | E53: =Input!AA3 -> Q. 26 | F53: =Input!AB3 -> Q. 27 | G53: =Input!AC3 -> Q. 28 | H53: =Input!AD3 -> Q. 29
B54: 5 | C54: =COUNTIF(Input!Y$4:'Input'!Y$68, "5")/$F$2*100 -> 73.529412 | D54: =COUNTIF(Input!Z$4:'Input'!Z$68, "5")/$F$2*100 -> 67.647059 | E54: =COUNTIF(Input!AA$4:'Input'!AA$68, "5")/$F$2*100 -> 58.823529 | F54: =COUNTIF(Input!AB$4:'Input'!AB$68, "5")/$F$2*100 -> 67.647059 | G54: =COUNTIF(Input!AC$4:'Input'!AC$68, "5")/$F$2*100 -> 58.823529 | H54: =COUNTIF(Input!AD$4:'Input'!AD$68, "5")/$F$2*100 -> 67.647059
...

Sheet Final Feedback
A1: Department of Electronics & Telecommunication Engineering
A2: Rajshahi University of Engineering Technology
A3: Students' Feedback on CSE 1254 (Object Oriented Programing)
A4: Course Teacher: Md Abu Ismail Siddique, Assistant Professor, Dept of ETE
A5: Session: 2023-24
A7: A. CORE QUESTIONS
A9: Sl. | B9: Course Content and Organization
A10: 1 | B10: The course objectives were clear
A11: 2 | B11: The course workload was manageable
A12: 3 | B12: The course was well organized (e.g., timely access to materials, notification of changes etc.)
A13: 4 | B13: Comments (if any): No comments
A15: Sl. | B15: Student Contribution
A16: 5 | B16: I participated actively in the course
A17: 6 | B17: I think I have made progress in this course
A18: 7 | B18: Comments (if any): No comments
A20: Sl. | B20: Learning Environment and Teaching Methods
A21: 8 | B21: I think the course was well structured to achieve the learning outcomes (there was a good balance of lectures)
A22: 9 | B22: The learning and teaching methods encouraged participation
A23: 10 | B23: The overall environment in the class was conductive to learning
A24: 11 | B24: Classrooms were satisfactory
A25: 12 | B25: Comments (if any): No comments
A27: Sl. | B27: Learning Resources
A28: 13 | B28: Learning materials (Lesson plans, course notes etc.) were relevant and useful
A29: 14 | B29: Recommended reading books etc. were relevant and appropriate
A30: 15 | B30: The provision of learning resources in the library was adequate and appropriate
A31: 16 | B31: Comments (if any): No comments
A34: Sl. | B34: Course Teacher
A35: 17 | B35: Course teacher showed empathy and helped solving critical problems
A36: 18 | B36: You felt that course teacher is an expert of this course
A37: 19 | B37: Delivery skill of teacher was satisfactory
A38: 20 | B38: Course teacher responded to your queries
A39: 21 | B39: Communication skill of teacher was satisfactory
A40: 22 | B40: You felt comfortable expressing your problems to your course teacher
A41: 23 | B41: Comments (if any): No comments
A43: B. COURSE RATING
A45: Sl. | B45: Criteria for Rating
A46: 24 | B46: Course Structure and Contents
A47: 25 | B47: Delivery Quality of Teacher
A48: 26 | B48: Course Duration
A49: 27 | B49: Environment
...
